<?xml version="1.0"?>
<robot name="my_robot" xmlns:xacro="http://www.ros.org/wiki/xacro">

    <xacro:property name="base_length" value="0.6" />
    <xacro:property name="base_width" value="0.4" />
    <xacro:property name="base_height" value="0.2" />
    
    <xacro:property name="wheel_radius" value="0.1" />
    <xacro:property name="wheel_length" value="0.05" />

    <material name="green">
        <color rgba="0 0.5 0 1" />
    </material>

    <material name="blue">
        <color rgba="0 0 0.5 1" />
    </material>

    <link name="base_footprint" />

    <link name="base_link">
        <visual>
            <geometry>
                <box size="${base_length} ${base_width} ${base_height}" />
            </geometry>
            <origin xyz="0.0 0.0 ${base_height / 2.0}" rpy="0 0 0" />
            <material name="green" />
        </visual>
    </link>

    <joint name="base_footprint_joint" type="fixed">
        <parent link="base_footprint" />
        <child link="base_link" />
        <origin xyz="0 0 ${base_height / 2.0}" rpy="0 0 0" />
    </joint>


    <xacro:macro name="wheel" params="prefix x_reflect y_reflect">
        
        <link name="${prefix}_wheel_link">
            <visual>
                <geometry>
                    <cylinder radius="${wheel_radius}" length="${wheel_length}" />
                </geometry>
                <origin xyz="0 0 0" rpy="1.5708 0 0" />
                <material name="blue" />
            </visual>
        </link>

        <joint name="base_${prefix}_wheel_joint" type="continuous">
            <parent link="base_link" />
            <child link="${prefix}_wheel_link" />
            <origin xyz="${x_reflect * (base_length / 4.0)} ${y_reflect * 0.225} -${base_height / 2.0}" rpy="0 0 0" />
            <axis xyz="0 1 0" />
        </joint>

    </xacro:macro>

    <xacro:wheel prefix="front_right" x_reflect="1"  y_reflect="-1" />
    <xacro:wheel prefix="front_left"  x_reflect="1"  y_reflect="1" />
    <xacro:wheel prefix="rear_right"  x_reflect="-1" y_reflect="-1" />
    <xacro:wheel prefix="rear_left"   x_reflect="-1" y_reflect="1" />

</robot>